[2024-03-20T13:59:34.230+0000] {processor.py:161} INFO - Started process (PID=75) to work on /home/airflow/.local/lib/python3.8/site-packages/airflow/example_dags/example_latest_only_with_trigger.py
[2024-03-20T13:59:34.234+0000] {processor.py:830} INFO - Processing file /home/airflow/.local/lib/python3.8/site-packages/airflow/example_dags/example_latest_only_with_trigger.py for tasks to queue
[2024-03-20T13:59:34.238+0000] {logging_mixin.py:188} INFO - [2024-03-20T13:59:34.238+0000] {dagbag.py:540} INFO - Filling up the DagBag from /home/airflow/.local/lib/python3.8/site-packages/airflow/example_dags/example_latest_only_with_trigger.py
[2024-03-20T13:59:43.575+0000] {logging_mixin.py:188} INFO - [2024-03-20T13:59:43.575+0000] {process_utils.py:262} INFO - Waiting up to 5 seconds for processes to exit...
[2024-03-20T14:00:13.057+0000] {processor.py:161} INFO - Started process (PID=84) to work on /home/airflow/.local/lib/python3.8/site-packages/airflow/example_dags/example_latest_only_with_trigger.py
[2024-03-20T14:00:13.066+0000] {processor.py:830} INFO - Processing file /home/airflow/.local/lib/python3.8/site-packages/airflow/example_dags/example_latest_only_with_trigger.py for tasks to queue
[2024-03-20T14:00:13.076+0000] {logging_mixin.py:188} INFO - [2024-03-20T14:00:13.075+0000] {dagbag.py:540} INFO - Filling up the DagBag from /home/airflow/.local/lib/python3.8/site-packages/airflow/example_dags/example_latest_only_with_trigger.py
[2024-03-20T14:00:13.173+0000] {processor.py:840} INFO - DAG(s) 'latest_only_with_trigger' retrieved from /home/airflow/.local/lib/python3.8/site-packages/airflow/example_dags/example_latest_only_with_trigger.py
[2024-03-20T14:00:15.211+0000] {logging_mixin.py:188} INFO - [2024-03-20T14:00:15.210+0000] {dag.py:3047} INFO - Sync 1 DAGs
[2024-03-20T14:00:15.340+0000] {logging_mixin.py:188} INFO - [2024-03-20T14:00:15.337+0000] {dag.py:3834} INFO - Setting next_dagrun for latest_only_with_trigger to 2024-03-20 08:00:00+00:00, run_after=2024-03-20 12:00:00+00:00
[2024-03-20T14:00:15.611+0000] {processor.py:183} INFO - Processing /home/airflow/.local/lib/python3.8/site-packages/airflow/example_dags/example_latest_only_with_trigger.py took 2.577 seconds
[2024-03-20T14:01:19.520+0000] {processor.py:161} INFO - Started process (PID=146) to work on /home/airflow/.local/lib/python3.8/site-packages/airflow/example_dags/example_latest_only_with_trigger.py
[2024-03-20T14:01:19.536+0000] {processor.py:830} INFO - Processing file /home/airflow/.local/lib/python3.8/site-packages/airflow/example_dags/example_latest_only_with_trigger.py for tasks to queue
[2024-03-20T14:01:19.598+0000] {logging_mixin.py:188} INFO - [2024-03-20T14:01:19.597+0000] {dagbag.py:540} INFO - Filling up the DagBag from /home/airflow/.local/lib/python3.8/site-packages/airflow/example_dags/example_latest_only_with_trigger.py
[2024-03-20T14:01:19.627+0000] {processor.py:840} INFO - DAG(s) 'latest_only_with_trigger' retrieved from /home/airflow/.local/lib/python3.8/site-packages/airflow/example_dags/example_latest_only_with_trigger.py
[2024-03-20T14:01:19.721+0000] {logging_mixin.py:188} INFO - [2024-03-20T14:01:19.720+0000] {dag.py:3047} INFO - Sync 1 DAGs
[2024-03-20T14:01:19.808+0000] {logging_mixin.py:188} INFO - [2024-03-20T14:01:19.807+0000] {dag.py:3834} INFO - Setting next_dagrun for latest_only_with_trigger to 2024-03-20 08:00:00+00:00, run_after=2024-03-20 12:00:00+00:00
[2024-03-20T14:01:19.928+0000] {processor.py:183} INFO - Processing /home/airflow/.local/lib/python3.8/site-packages/airflow/example_dags/example_latest_only_with_trigger.py took 0.429 seconds
[2024-03-20T14:02:03.524+0000] {processor.py:161} INFO - Started process (PID=202) to work on /home/airflow/.local/lib/python3.8/site-packages/airflow/example_dags/example_latest_only_with_trigger.py
[2024-03-20T14:02:03.550+0000] {processor.py:830} INFO - Processing file /home/airflow/.local/lib/python3.8/site-packages/airflow/example_dags/example_latest_only_with_trigger.py for tasks to queue
[2024-03-20T14:02:03.574+0000] {logging_mixin.py:188} INFO - [2024-03-20T14:02:03.573+0000] {dagbag.py:540} INFO - Filling up the DagBag from /home/airflow/.local/lib/python3.8/site-packages/airflow/example_dags/example_latest_only_with_trigger.py
[2024-03-20T14:02:03.722+0000] {processor.py:840} INFO - DAG(s) 'latest_only_with_trigger' retrieved from /home/airflow/.local/lib/python3.8/site-packages/airflow/example_dags/example_latest_only_with_trigger.py
[2024-03-20T14:02:04.229+0000] {logging_mixin.py:188} INFO - [2024-03-20T14:02:04.228+0000] {dag.py:3047} INFO - Sync 1 DAGs
[2024-03-20T14:02:04.800+0000] {logging_mixin.py:188} INFO - [2024-03-20T14:02:04.799+0000] {dag.py:3834} INFO - Setting next_dagrun for latest_only_with_trigger to 2024-03-20 08:00:00+00:00, run_after=2024-03-20 12:00:00+00:00
[2024-03-20T14:02:05.960+0000] {processor.py:183} INFO - Processing /home/airflow/.local/lib/python3.8/site-packages/airflow/example_dags/example_latest_only_with_trigger.py took 2.563 seconds
[2024-03-20T14:04:28.124+0000] {processor.py:161} INFO - Started process (PID=268) to work on /home/airflow/.local/lib/python3.8/site-packages/airflow/example_dags/example_latest_only_with_trigger.py
[2024-03-20T14:04:28.135+0000] {processor.py:830} INFO - Processing file /home/airflow/.local/lib/python3.8/site-packages/airflow/example_dags/example_latest_only_with_trigger.py for tasks to queue
[2024-03-20T14:04:28.187+0000] {logging_mixin.py:188} INFO - [2024-03-20T14:04:28.173+0000] {dagbag.py:540} INFO - Filling up the DagBag from /home/airflow/.local/lib/python3.8/site-packages/airflow/example_dags/example_latest_only_with_trigger.py
[2024-03-20T14:04:28.397+0000] {processor.py:840} INFO - DAG(s) 'latest_only_with_trigger' retrieved from /home/airflow/.local/lib/python3.8/site-packages/airflow/example_dags/example_latest_only_with_trigger.py
[2024-03-20T14:05:00.044+0000] {processor.py:186} ERROR - Got an exception! Propagating...
Traceback (most recent call last):
  File "/home/airflow/.local/lib/python3.8/site-packages/sqlalchemy/engine/base.py", line 3371, in _wrap_pool_connect
    return fn()
  File "/home/airflow/.local/lib/python3.8/site-packages/sqlalchemy/pool/base.py", line 327, in connect
    return _ConnectionFairy._checkout(self)
  File "/home/airflow/.local/lib/python3.8/site-packages/sqlalchemy/pool/base.py", line 894, in _checkout
    fairy = _ConnectionRecord.checkout(pool)
  File "/home/airflow/.local/lib/python3.8/site-packages/sqlalchemy/pool/base.py", line 493, in checkout
    rec = pool._do_get()
  File "/home/airflow/.local/lib/python3.8/site-packages/sqlalchemy/pool/impl.py", line 146, in _do_get
    self._dec_overflow()
  File "/home/airflow/.local/lib/python3.8/site-packages/sqlalchemy/util/langhelpers.py", line 70, in __exit__
    compat.raise_(
  File "/home/airflow/.local/lib/python3.8/site-packages/sqlalchemy/util/compat.py", line 211, in raise_
    raise exception
  File "/home/airflow/.local/lib/python3.8/site-packages/sqlalchemy/pool/impl.py", line 143, in _do_get
    return self._create_connection()
  File "/home/airflow/.local/lib/python3.8/site-packages/sqlalchemy/pool/base.py", line 273, in _create_connection
    return _ConnectionRecord(self)
  File "/home/airflow/.local/lib/python3.8/site-packages/sqlalchemy/pool/base.py", line 388, in __init__
    self.__connect()
  File "/home/airflow/.local/lib/python3.8/site-packages/sqlalchemy/pool/base.py", line 691, in __connect
    pool.logger.debug("Error on connect(): %s", e)
  File "/home/airflow/.local/lib/python3.8/site-packages/sqlalchemy/util/langhelpers.py", line 70, in __exit__
    compat.raise_(
  File "/home/airflow/.local/lib/python3.8/site-packages/sqlalchemy/util/compat.py", line 211, in raise_
    raise exception
  File "/home/airflow/.local/lib/python3.8/site-packages/sqlalchemy/pool/base.py", line 686, in __connect
    self.dbapi_connection = connection = pool._invoke_creator(self)
  File "/home/airflow/.local/lib/python3.8/site-packages/sqlalchemy/engine/create.py", line 574, in connect
    return dialect.connect(*cargs, **cparams)
  File "/home/airflow/.local/lib/python3.8/site-packages/sqlalchemy/engine/default.py", line 598, in connect
    return self.dbapi.connect(*cargs, **cparams)
  File "/home/airflow/.local/lib/python3.8/site-packages/psycopg2/__init__.py", line 122, in connect
    conn = _connect(dsn, connection_factory=connection_factory, **kwasync)
psycopg2.OperationalError: could not translate host name "postgres" to address: Temporary failure in name resolution


The above exception was the direct cause of the following exception:

Traceback (most recent call last):
  File "/home/airflow/.local/lib/python3.8/site-packages/airflow/dag_processing/processor.py", line 182, in _run_file_processor
    _handle_dag_file_processing()
  File "/home/airflow/.local/lib/python3.8/site-packages/airflow/dag_processing/processor.py", line 163, in _handle_dag_file_processing
    result: tuple[int, int] = dag_file_processor.process_file(
  File "/home/airflow/.local/lib/python3.8/site-packages/airflow/utils/session.py", line 79, in wrapper
    return func(*args, session=session, **kwargs)
  File "/home/airflow/.local/lib/python3.8/site-packages/airflow/dag_processing/processor.py", line 859, in process_file
    serialize_errors = DagFileProcessor.save_dag_to_db(
  File "/home/airflow/.local/lib/python3.8/site-packages/airflow/api_internal/internal_api_call.py", line 114, in wrapper
    return func(*args, **kwargs)
  File "/home/airflow/.local/lib/python3.8/site-packages/airflow/utils/session.py", line 79, in wrapper
    return func(*args, session=session, **kwargs)
  File "/home/airflow/.local/lib/python3.8/site-packages/airflow/dag_processing/processor.py", line 895, in save_dag_to_db
    import_errors = DagBag._sync_to_db(dags=dags, processor_subdir=dag_directory, session=session)
  File "/home/airflow/.local/lib/python3.8/site-packages/airflow/utils/session.py", line 76, in wrapper
    return func(*args, **kwargs)
  File "/home/airflow/.local/lib/python3.8/site-packages/airflow/models/dagbag.py", line 659, in _sync_to_db
    for attempt in run_with_db_retries(logger=log):
  File "/home/airflow/.local/lib/python3.8/site-packages/tenacity/__init__.py", line 347, in __iter__
    do = self.iter(retry_state=retry_state)
  File "/home/airflow/.local/lib/python3.8/site-packages/tenacity/__init__.py", line 325, in iter
    raise retry_exc.reraise()
  File "/home/airflow/.local/lib/python3.8/site-packages/tenacity/__init__.py", line 158, in reraise
    raise self.last_attempt.result()
  File "/usr/local/lib/python3.8/concurrent/futures/_base.py", line 437, in result
    return self.__get_result()
  File "/usr/local/lib/python3.8/concurrent/futures/_base.py", line 389, in __get_result
    raise self._exception
  File "/home/airflow/.local/lib/python3.8/site-packages/airflow/models/dagbag.py", line 672, in _sync_to_db
    _serialize_dag_capturing_errors(dag, session, processor_subdir)
  File "/home/airflow/.local/lib/python3.8/site-packages/airflow/models/dagbag.py", line 637, in _serialize_dag_capturing_errors
    dag_was_updated = SerializedDagModel.write_dag(
  File "/home/airflow/.local/lib/python3.8/site-packages/airflow/utils/session.py", line 76, in wrapper
    return func(*args, **kwargs)
  File "/home/airflow/.local/lib/python3.8/site-packages/airflow/models/serialized_dag.py", line 157, in write_dag
    if session.scalar(
  File "/home/airflow/.local/lib/python3.8/site-packages/sqlalchemy/orm/session.py", line 1747, in scalar
    return self.execute(
  File "/home/airflow/.local/lib/python3.8/site-packages/sqlalchemy/orm/session.py", line 1716, in execute
    conn = self._connection_for_bind(bind)
  File "/home/airflow/.local/lib/python3.8/site-packages/sqlalchemy/orm/session.py", line 1555, in _connection_for_bind
    return self._transaction._connection_for_bind(
  File "/home/airflow/.local/lib/python3.8/site-packages/sqlalchemy/orm/session.py", line 750, in _connection_for_bind
    conn = bind.connect()
  File "/home/airflow/.local/lib/python3.8/site-packages/sqlalchemy/future/engine.py", line 412, in connect
    return super(Engine, self).connect()
  File "/home/airflow/.local/lib/python3.8/site-packages/sqlalchemy/engine/base.py", line 3325, in connect
    return self._connection_cls(self, close_with_result=close_with_result)
  File "/home/airflow/.local/lib/python3.8/site-packages/sqlalchemy/engine/base.py", line 96, in __init__
    else engine.raw_connection()
  File "/home/airflow/.local/lib/python3.8/site-packages/sqlalchemy/engine/base.py", line 3404, in raw_connection
    return self._wrap_pool_connect(self.pool.connect, _connection)
  File "/home/airflow/.local/lib/python3.8/site-packages/sqlalchemy/engine/base.py", line 3374, in _wrap_pool_connect
    Connection._handle_dbapi_exception_noconnection(
  File "/home/airflow/.local/lib/python3.8/site-packages/sqlalchemy/engine/base.py", line 2208, in _handle_dbapi_exception_noconnection
    util.raise_(
  File "/home/airflow/.local/lib/python3.8/site-packages/sqlalchemy/util/compat.py", line 211, in raise_
    raise exception
  File "/home/airflow/.local/lib/python3.8/site-packages/sqlalchemy/engine/base.py", line 3371, in _wrap_pool_connect
    return fn()
  File "/home/airflow/.local/lib/python3.8/site-packages/sqlalchemy/pool/base.py", line 327, in connect
    return _ConnectionFairy._checkout(self)
  File "/home/airflow/.local/lib/python3.8/site-packages/sqlalchemy/pool/base.py", line 894, in _checkout
    fairy = _ConnectionRecord.checkout(pool)
  File "/home/airflow/.local/lib/python3.8/site-packages/sqlalchemy/pool/base.py", line 493, in checkout
    rec = pool._do_get()
  File "/home/airflow/.local/lib/python3.8/site-packages/sqlalchemy/pool/impl.py", line 146, in _do_get
    self._dec_overflow()
  File "/home/airflow/.local/lib/python3.8/site-packages/sqlalchemy/util/langhelpers.py", line 70, in __exit__
    compat.raise_(
  File "/home/airflow/.local/lib/python3.8/site-packages/sqlalchemy/util/compat.py", line 211, in raise_
    raise exception
  File "/home/airflow/.local/lib/python3.8/site-packages/sqlalchemy/pool/impl.py", line 143, in _do_get
    return self._create_connection()
  File "/home/airflow/.local/lib/python3.8/site-packages/sqlalchemy/pool/base.py", line 273, in _create_connection
    return _ConnectionRecord(self)
  File "/home/airflow/.local/lib/python3.8/site-packages/sqlalchemy/pool/base.py", line 388, in __init__
    self.__connect()
  File "/home/airflow/.local/lib/python3.8/site-packages/sqlalchemy/pool/base.py", line 691, in __connect
    pool.logger.debug("Error on connect(): %s", e)
  File "/home/airflow/.local/lib/python3.8/site-packages/sqlalchemy/util/langhelpers.py", line 70, in __exit__
    compat.raise_(
  File "/home/airflow/.local/lib/python3.8/site-packages/sqlalchemy/util/compat.py", line 211, in raise_
    raise exception
  File "/home/airflow/.local/lib/python3.8/site-packages/sqlalchemy/pool/base.py", line 686, in __connect
    self.dbapi_connection = connection = pool._invoke_creator(self)
  File "/home/airflow/.local/lib/python3.8/site-packages/sqlalchemy/engine/create.py", line 574, in connect
    return dialect.connect(*cargs, **cparams)
  File "/home/airflow/.local/lib/python3.8/site-packages/sqlalchemy/engine/default.py", line 598, in connect
    return self.dbapi.connect(*cargs, **cparams)
  File "/home/airflow/.local/lib/python3.8/site-packages/psycopg2/__init__.py", line 122, in connect
    conn = _connect(dsn, connection_factory=connection_factory, **kwasync)
sqlalchemy.exc.OperationalError: (psycopg2.OperationalError) could not translate host name "postgres" to address: Temporary failure in name resolution

(Background on this error at: https://sqlalche.me/e/14/e3q8)
